Workbook

Sheet Checklist
A1: DEFINITION OF DONE — Sistema de Gestión de Reserva Hotelera | F1: RESUMEN POR CATEGORÍA | L1: ESCALA DE VALORES
L2: Valor 0 | M2: Valor 1 | N2: Valor 2 | O2: Valor 3
L3: No cumplido | M3: A veces | N3: Frecuentemente | O3: Siempre
L4: 0 | M4: 1 | N4: 2 | O4: 3
A5: CATEGORÍA | B5: COMPONENTE / VISTA | C5: CRITERIO DOD | D5: VALOR | F5: CATEGORÍA | I5: MEDIA
A6: ARTEFACTOS | B6: Vista Escenario (Caso de Uso) | C6: El diagrama de caso de uso representa correctamente actores, casos y relaciones del sistema hotelero. | D6: 3 | F6: ARTEFACTOS | I6: MEDIA
C7: Los casos de uso están validados con el Product Owner (George Solo) y los stakeholders. | D7: 3 | F7: Vista Escenario (Caso de Uso) | I7: =SUM(D6:D9)/12 -> 1
C8: El diagrama está versionado en el repositorio Git con mínimo 3 commits. | D8: 3 | F8: Vista de Procesos (Actividad) | I8: =SUM(D10:D13)/12 -> 1
C9: El artefacto fue cargado en Trello en estado 'Revisión'. | D9: 3 | F9: Vista Lógica (Clases) | I9: =SUM(D14:D17)/12 -> 1
B10: Vista de Procesos (Diagrama de Actividad) | C10: El diagrama de actividad modela correctamente el flujo de reserva de habitación (inicio → pago → QR). | D10: 3 | F10: Vista Despliegue (Componentes) | I10: =SUM(D18:D21)/12 -> 1
C11: Los flujos paralelos y secuenciales del Roadmap están reflejados en el diagrama. | D11: 3 | F11: Total ARTEFACTOS | I11: =AVERAGE(I7:I10) -> 1
C12: El artefacto está versionado en Git y cargado en Trello. | D12: 3 | F12: PROTOTIPO | I12: MEDIA
C13: El diagrama cumple el estándar UML 2.0. | D13: 3 | F13: Dashboard Administración | I13: =SUM(D22:D25)/12 -> 0.91666667
B14: Vista Lógica (Diagrama de Clases) | C14: El diagrama de clases refleja las entidades: Reserva, Habitación, Cliente, Pago, Empleado. | D14: 3 | F14: Listado / Búsqueda de Habitaciones | I14: =SUM(D26:D29)/12 -> 0.91666667
C15: Las relaciones (herencia, asociación, composición) están correctamente tipadas. | D15: 3 | F15: Formulario de Reserva | I15: =SUM(D30:D33)/12 -> 0.83333333
C16: Los atributos y métodos de cada clase son coherentes con el CRUD del negocio. | D16: 3 | F16: Total PROTOTIPO | I16: =AVERAGE(I13:I15) -> 0.88888889
C17: El artefacto está versionado en Git y cargado en Trello. | D17: 3 | F17: GIT & HERRAMIENTAS | I17: MEDIA
B18: Vista Despliegue (Diagrama de Componentes) | C18: El diagrama de componentes representa las 4 capas: Presentación, Lógica, Acceso a Datos y BD. | D18: 3 | F18: Control de Versiones (Git) | I18: =SUM(D34:D37)/12 -> 1
C19: Los componentes front-end (vistas) y back-end (servicios) están correctamente diferenciados. | D19: 3 | F19: Trello | I19: =SUM(D38:D41)/12 -> 0.91666667
C20: Se especifican las interfaces de comunicación entre capas (REST, ORM, JDBC). | D20: 3 | F20: Total GIT & HERRAMIENTAS | I20: =AVERAGE(I18:I19) -> 0.95833333
C21: El artefacto está versionado en Git y cargado en Trello. | D21: 3 | F21: CUMPLIMIENTO GLOBAL DOD | I21: =AVERAGE(I7,I12,I16,I20,I24) -> 0.94907407
A22: PROTOTIPO (Vistas UI) | B22: Dashboard Administración | C22: El dashboard muestra KPIs: reservas activas, habitaciones ocupadas, ingresos del mes, check-ins. | D22: 3
C23: La tabla de últimas reservas muestra estados (Confirmada, Pendiente, Cancelada) con colores. | D23: 3
C24: El gráfico de ocupación por tipo de habitación está implementado. | D24: 3
C25: La vista cumple criterios de accesibilidad y usabilidad (contraste, jerarquía visual). | D25: 2
B26: Listado / Búsqueda de Habitaciones | C26: Las habitaciones se muestran en tarjetas con número, tipo, precio, amenidades y estado. | D26: 3
C27: Los filtros por estado (Disponible, Ocupada, Mantenimiento) y tipo funcionan correctamente. | D27: 3
C28: El buscador permite filtrar por número de habitación o tipo. | D28: 2
C29: El badge de estado usa colores semánticos (verde, rojo, amarillo). | D29: 3
B30: Formulario de Reserva | C30: El formulario captura: datos del cliente, habitación, fechas, nro. huéspedes y método de pago. | D30: 3
C31: El panel lateral de resumen muestra precio/noche, noches, impuesto y total dinámicamente. | D31: 3
C32: Los campos tienen validación (fechas, email, RUT). | D32: 2
C33: Se envía confirmación por correo al confirmar la reserva. | D33: 2
A34: GIT & HERRAMIENTAS | B34: Control de Versiones (Git) | C34: El repositorio tiene mínimo 3 commits por elemento de diseño desarrollado. | D34: 3
C35: Los commits tienen mensajes descriptivos y están asociados a las historias de usuario. | D35: 3
C36: La URL pública del repositorio está compartida con el instructor. | D36: 3
C37: Los archivos fuente de los diseños (imágenes, Figma exports) están en el repositorio. | D37: 3
B38: Trello | C38: Las tarjetas de diseño están en estado 'Revisión' con imágenes adjuntas. | D38: 3
C39: El tablero refleja el avance real del sprint (columnas: To Do, In Progress, Done). | D39: 3
C40: El video narrativo (3-5 min) está adjunto como link en el tablero. | D40: 2
...

Sheet Resultados
A1: RESULTADOS DOD — Sistema de Gestión de Reserva Hotelera
A2: Categoría | B2: Cumplimiento | C2: Estado
A3: Artefactos — Vista Escenario | B3: =Checklist!I7 -> 1 | C3: =IF(B3>=0.8,"✓ Logrado",IF(B3>=0.6,"~ Medianamente Logrado","✗ Insuficiente")) -> ✓ Logrado
A4: Artefactos — Vista de Procesos | B4: =Checklist!I8 -> 1 | C4: =IF(B4>=0.8,"✓ Logrado",IF(B4>=0.6,"~ Medianamente Logrado","✗ Insuficiente")) -> ✓ Logrado
A5: Artefactos — Vista Lógica | B5: =Checklist!I9 -> 1 | C5: =IF(B5>=0.8,"✓ Logrado",IF(B5>=0.6,"~ Medianamente Logrado","✗ Insuficiente")) -> ✓ Logrado
A6: Artefactos — Vista Despliegue | B6: =Checklist!I10 -> 1 | C6: =IF(B6>=0.8,"✓ Logrado",IF(B6>=0.6,"~ Medianamente Logrado","✗ Insuficiente")) -> ✓ Logrado
A7: Prototipo — Dashboard | B7: =Checklist!I12 -> MEDIA | C7: =IF(B7>=0.8,"✓ Logrado",IF(B7>=0.6,"~ Medianamente Logrado","✗ Insuficiente")) -> ✓ Logrado
A8: Prototipo — Listado Habitaciones | B8: =Checklist!I13 -> 0.91666667 | C8: =IF(B8>=0.8,"✓ Logrado",IF(B8>=0.6,"~ Medianamente Logrado","✗ Insuficiente")) -> ✓ Logrado
A9: Prototipo — Formulario Reserva | B9: =Checklist!I14 -> 0.91666667 | C9: =IF(B9>=0.8,"✓ Logrado",IF(B9>=0.6,"~ Medianamente Logrado","✗ Insuficiente")) -> ✓ Logrado
A10: Git — Control de Versiones | B10: =Checklist!I16 -> 0.88888889 | C10: =IF(B10>=0.8,"✓ Logrado",IF(B10>=0.6,"~ Medianamente Logrado","✗ Insuficiente")) -> ✓ Logrado
A11: Git — Trello | B11: =Checklist!I17 -> MEDIA | C11: =IF(B11>=0.8,"✓ Logrado",IF(B11>=0.6,"~ Medianamente Logrado","✗ Insuficiente")) -> ✓ Logrado
A12: CUMPLIMIENTO GLOBAL | B12: =AVERAGE(B3:B11) -> 0.96031746 | C12: =IF(B12>=0.8,"✓ Completamente Logrado",IF(B12>=0.6,"~ Medianamente Logrado","✗ Insuficiente")) -> ✓ Completamente Logrado
